Workbook

Sheet OrigInvent2023LTO
B2: CALSIM | C2: AW_EDCOCA_NA1 | D2: AG-DEMAND | E2: 1MON | F2: L2020A | G2: =_xlfn.CONCAT(C2,"/",D2) -> AW_EDCOCA_NA1/AG-DEMAND | H2: Miscellaneous | I2: https://cadwr.box.com/s/7y5d3wa9cs1eoeanw7wrflmc1j1hej2x | K2: Timseries set to 0. Related Source Documentation File and Text File provided in Water Management Plan Folder | L2: Both | N2: TAF
B3: CALSIM | C3: AW_EDCOCA_NA2 | D3: AG-DEMAND | E3: 1MON | F3: L2020A | G3: =_xlfn.CONCAT(C3,"/",D3) -> AW_EDCOCA_NA2/AG-DEMAND | H3: Miscellaneous | I3: https://cadwr.box.com/s/7y5d3wa9cs1eoeanw7wrflmc1j1hej2x | K3: Timseries set to 0. Related Source Documentation File and Text File provided in Water Management Plan Folder | L3: Both | N3: TAF
B4: CALSIM | C4: AW_EDCOCA_NA3 | D4: AG-DEMAND | E4: 1MON | F4: L2020A | G4: =_xlfn.CONCAT(C4,"/",D4) -> AW_EDCOCA_NA3/AG-DEMAND | H4: Miscellaneous | I4: https://cadwr.box.com/s/7y5d3wa9cs1eoeanw7wrflmc1j1hej2x | K4: Timseries set to 0. Related Source Documentation File and Text File provided in Water Management Plan Folder | L4: Both | N4: TAF
B5: CALSIM | C5: AW_ELDID_NA1 | D5: AG-DEMAND | E5: 1MON | F5: L2020A | G5: =_xlfn.CONCAT(C5,"/",D5) -> AW_ELDID_NA1/AG-DEMAND | H5: Miscellaneous | I5: https://cadwr.box.com/s/7y5d3wa9cs1eoeanw7wrflmc1j1hej2x | K5: Repeating 12 month value timeseries; Data pulled from EDCWA WRDMP | L5: Both | N5: TAF
B6: CALSIM | C6: AW_ELDID_NA2 | D6: AG-DEMAND | E6: 1MON | F6: L2020A | G6: =_xlfn.CONCAT(C6,"/",D6) -> AW_ELDID_NA2/AG-DEMAND | H6: Miscellaneous | I6: https://cadwr.box.com/s/7y5d3wa9cs1eoeanw7wrflmc1j1hej2x | K6: Repeating 12 month value timeseries; Data pulled from EDCWA WRDMP | L6: Both | N6: TAF
B7: CALSIM | C7: AW_ELDID_NA3 | D7: AG-DEMAND | E7: 1MON | F7: L2020A | G7: =_xlfn.CONCAT(C7,"/",D7) -> AW_ELDID_NA3/AG-DEMAND | H7: Miscellaneous | I7: https://cadwr.box.com/s/7y5d3wa9cs1eoeanw7wrflmc1j1hej2x | K7: Repeating 12 month value timeseries; Data pulled from EDCWA WRDMP | L7: Both | N7: TAF
B8: CALSIM | C8: AW_GDPUD_NA | D8: AG-DEMAND | E8: 1MON | F8: L2020A | G8: =_xlfn.CONCAT(C8,"/",D8) -> AW_GDPUD_NA/AG-DEMAND | H8: Miscellaneous | I8: https://cadwr.box.com/s/7y5d3wa9cs1eoeanw7wrflmc1j1hej2x | K8: Repeating 12 month value timeseries; Data pulled from EDCWA WRDMP | L8: Both | N8: TAF
B9: CALSIM | C9: AW_NIDBR_NA | D9: APPLIED-WATER | E9: 1MON | F9: L2020A | G9: =_xlfn.CONCAT(C9,"/",D9) -> AW_NIDBR_NA/APPLIED-WATER | H9: Miscellaneous | I9: https://cadwr.box.com/s/7y5d3wa9cs1eoeanw7wrflmc1j1hej2x | K9: NID Water Management plan; Repeating 12 month value timeseries | L9: Both | N9: TAF
B10: CALSIM | C10: AW_NIDDC_NA1 | D10: APPLIED-WATER | E10: 1MON | F10: L2020A | G10: =_xlfn.CONCAT(C10,"/",D10) -> AW_NIDDC_NA1/APPLIED-WATER | H10: Miscellaneous | I10: https://cadwr.box.com/s/7y5d3wa9cs1eoeanw7wrflmc1j1hej2x | K10: NID Water Management plan; Repeating 12 month value timeseries | L10: Both | N10: TAF
B11: CALSIM | C11: AW_NIDDC_NA2 | D11: APPLIED-WATER | E11: 1MON | F11: L2020A | G11: =_xlfn.CONCAT(C11,"/",D11) -> AW_NIDDC_NA2/APPLIED-WATER | H11: Miscellaneous | I11: https://cadwr.box.com/s/7y5d3wa9cs1eoeanw7wrflmc1j1hej2x | K11: NID Water Management plan; Repeating 12 month value timeseries | L11: Both | N11: TAF
B12: CALSIM | C12: AW_NIDDC_NA3 | D12: APPLIED-WATER | E12: 1MON | F12: L2020A | G12: =_xlfn.CONCAT(C12,"/",D12) -> AW_NIDDC_NA3/APPLIED-WATER | H12: Miscellaneous | I12: https://cadwr.box.com/s/7y5d3wa9cs1eoeanw7wrflmc1j1hej2x | K12: NID Water Management plan; Repeating 12 month value timeseries | L12: Both | N12: TAF
B13: CALSIM | C13: SG_R3_CVP | D13: CANAL-LOSS | E13: 1MON | F13: L2020A | G13: =_xlfn.CONCAT(C13,"/",D13) -> SG_R3_CVP/CANAL-LOSS | H13: Miscellaneous | I13: https://cadwr.box.com/s/1r6d5e8e57cwdgr5zd5atbk03prm0mvn | K13: Repeating 12 month value timeseries; From CalSim3_Merge_05222018 deliveried from USBR | L13: Both | N13: TAF
... B23: CALSIM | C23: SG_R7_SWP | D23: CANAL-LOSS | E23: 1MON | F23: L2020A | G23: =_xlfn.CONCAT(C23,"/",D23) -> SG_R7_SWP/CANAL-LOSS | H23: Miscellaneous | I23: https://cadwr.box.com/s/1r6d5e8e57cwdgr5zd5atbk03prm0mvn | K23: Repeating 12 month value timeseries; From CalSim3_Merge_05222018 deliveried from USBR | L23: Both | N23: TAF
B24: CALSIM | C24: CL_DGR | D24: CONTRACT-LIMIT | E24: 1MON | F24: L2020A | G24: =_xlfn.CONCAT(C24,"/",D24) -> CL_DGR/CONTRACT-LIMIT | H24: Miscellaneous | I24: https://cadwr.box.com/s/ehdiqn3dsdyk2fulv51uz2rvj56lhghl | L24: No | M24: Yes | N24: TAF
B25: CALSIM | C25: DEM_D810_PIN | D25: DEMAND-SWP-IN | E25: 1MON | F25: L2020A | G25: =_xlfn.CONCAT(C25,"/",D25) -> DEM_D810_PIN/DEMAND-SWP-IN | H25: Miscellaneous | I25: https://cadwr.box.com/s/mz2dfvkwm1jsml6m96294j8akezo41o1 | K25: Renamed in CS3: DEM_D_SBA009_ACFC_PIN | L25: Both | N25: TAF
B26: CALSIM | C26: DEM_D814_PIN | D26: DEMAND-SWP-IN | E26: 1MON | F26: L2020A | G26: =_xlfn.CONCAT(C26,"/",D26) -> DEM_D814_PIN/DEMAND-SWP-IN | H26: Miscellaneous | I26: https://cadwr.box.com/s/mz2dfvkwm1jsml6m96294j8akezo41o1 | K26: Renamed in CS3: DEM_D_SBA029_ACWD_PIN | L26: Both | N26: TAF
B27: CALSIM | C27: DEM_D815_PIN | D27: DEMAND-SWP-IN | E27: 1MON | F27: L2020A | G27: =_xlfn.CONCAT(C27,"/",D27) -> DEM_D815_PIN/DEMAND-SWP-IN | H27: Miscellaneous | I27: https://cadwr.box.com/s/mz2dfvkwm1jsml6m96294j8akezo41o1 | K27: Renamed in CS3: DEM_D_SBA036_SCVWD_PIN | L27: Both | N27: TAF
B28: CALSIM | C28: DP_GWR15 | D28: DEEP-PERCOLATION | E28: 1MON | F28: L2020A | G28: =_xlfn.CONCAT(C28,"/",D28) -> DP_GWR15/DEEP-PERCOLATION | H28: Groundwater Models | I28: https://cadwr.box.com/s/qm8lwwmzfxl20b40d8axkyb6125cjrrp | L28: Both | M28: Precip Dependent | N28: TAF
B29: CALSIM | C29: DP_GWR16 | D29: DEEP-PERCOLATION | E29: 1MON | F29: L2020A | G29: =_xlfn.CONCAT(C29,"/",D29) -> DP_GWR16/DEEP-PERCOLATION | H29: Groundwater Models | I29: https://cadwr.box.com/s/qm8lwwmzfxl20b40d8axkyb6125cjrrp | L29: Both | M29: Precip Dependent | N29: TAF
B30: CALSIM | C30: DP_GWR17 | D30: DEEP-PERCOLATION | E30: 1MON | F30: L2020A | G30: =_xlfn.CONCAT(C30,"/",D30) -> DP_GWR17/DEEP-PERCOLATION | H30: Groundwater Models | I30: https://cadwr.box.com/s/qm8lwwmzfxl20b40d8axkyb6125cjrrp | L30: Both | M30: Precip Dependent | N30: TAF
B31: CALSIM | C31: DP_GWR18 | D31: DEEP-PERCOLATION | E31: 1MON | F31: L2020A | G31: =_xlfn.CONCAT(C31,"/",D31) -> DP_GWR18/DEEP-PERCOLATION | H31: Groundwater Models | I31: https://cadwr.box.com/s/qm8lwwmzfxl20b40d8axkyb6125cjrrp | L31: Both | M31: Precip Dependent | N31: TAF
B32: CALSIM | C32: DP_GWR19 | D32: DEEP-PERCOLATION | E32: 1MON | F32: L2020A | G32: =_xlfn.CONCAT(C32,"/",D32) -> DP_GWR19/DEEP-PERCOLATION | H32: Groundwater Models | I32: https://cadwr.box.com/s/qm8lwwmzfxl20b40d8axkyb6125cjrrp | L32: Both | M32: Precip Dependent | N32: TAF
B33: CALSIM | C33: DP_GWR20 | D33: DEEP-PERCOLATION | E33: 1MON | F33: L2020A | G33: =_xlfn.CONCAT(C33,"/",D33) -> DP_GWR20/DEEP-PERCOLATION | H33: Groundwater Models | I33: https://cadwr.box.com/s/qm8lwwmzfxl20b40d8axkyb6125cjrrp | L33: Both | M33: Precip Dependent | N33: TAF
B34: CALSIM | C34: DP_GWR21 | D34: DEEP-PERCOLATION | E34: 1MON | F34: L2020A | G34: =_xlfn.CONCAT(C34,"/",D34) -> DP_GWR21/DEEP-PERCOLATION | H34: Groundwater Models | I34: https://cadwr.box.com/s/qm8lwwmzfxl20b40d8axkyb6125cjrrp | L34: Both | M34: Precip Dependent | N34: TAF
B35: CALSIM | C35: DP_WBA50_DCD | D35: DP-FLOW | E35: 1MON | F35: L2020A | G35: =_xlfn.CONCAT(C35,"/",D35) -> DP_WBA50_DCD/DP-FLOW | H35: Groundwater Models | I35: https://cadwr.box.com/s/qm8lwwmzfxl20b40d8axkyb6125cjrrp | L35: Both | M35: Precip Dependent | N35: TAF
B36: CALSIM | C36: GP_GWR15 | D36: PUMPING | E36: 1MON | F36: L2020A | G36: =_xlfn.CONCAT(C36,"/",D36) -> GP_GWR15/PUMPING | H36: Groundwater Models | I36: https://cadwr.box.com/s/qm8lwwmzfxl20b40d8axkyb6125cjrrp | L36: Both | M36: No | N36: TAF
B37: CALSIM | C37: GP_GWR16 | D37: PUMPING | E37: 1MON | F37: L2020A | G37: =_xlfn.CONCAT(C37,"/",D37) -> GP_GWR16/PUMPING | H37: Groundwater Models | I37: https://cadwr.box.com/s/qm8lwwmzfxl20b40d8axkyb6125cjrrp | L37: Both | M37: No | N37: TAF
B38: CALSIM | C38: GP_GWR17 | D38: PUMPING | E38: 1MON | F38: L2020A | G38: =_xlfn.CONCAT(C38,"/",D38) -> GP_GWR17/PUMPING | H38: Groundwater Models | I38: https://cadwr.box.com/s/qm8lwwmzfxl20b40d8axkyb6125cjrrp | L38: Both | M38: No | N38: TAF
B39: CALSIM | C39: GP_GWR18 | D39: PUMPING | E39: 1MON | F39: L2020A | G39: =_xlfn.CONCAT(C39,"/",D39) -> GP_GWR18/PUMPING | H39: Groundwater Models | I39: https://cadwr.box.com/s/qm8lwwmzfxl20b40d8axkyb6125cjrrp | L39: Both | M39: No | N39: TAF
... B42: CALSIM | C42: GP_GWR21 | D42: PUMPING | E42: 1MON | F42: L2020A | G42: =_xlfn.CONCAT(C42,"/",D42) -> GP_GWR21/PUMPING | H42: Groundwater Models | I42: https://cadwr.box.com/s/qm8lwwmzfxl20b40d8axkyb6125cjrrp | L42: Both | M42: No | N42: TAF
B43: CALSIM | C43: GW1_N1003 | D43: BUGW-INFLOW | E43: 1MON | F43: L2020A | G43: =_xlfn.CONCAT(C43,"/",D43) -> GW1_N1003/BUGW-INFLOW | H43: Groundwater Models | I43: https://cadwr.box.com/s/qm8lwwmzfxl20b40d8axkyb6125cjrrp | L43: Both | N43: TAF
B44: CALSIM | C44: GW1_N1004 | D44: BUGW-INFLOW | E44: 1MON | F44: L2020A | G44: =_xlfn.CONCAT(C44,"/",D44) -> GW1_N1004/BUGW-INFLOW | H44: Groundwater Models | I44: https://cadwr.box.com/s/qm8lwwmzfxl20b40d8axkyb6125cjrrp | L44: Both | N44: TAF
B45: CALSIM | C45: GW1_N1005 | D45: BUGW-INFLOW | E45: 1MON | F45: L2020A | G45: =_xlfn.CONCAT(C45,"/",D45) -> GW1_N1005/BUGW-INFLOW | H45: Groundwater Models | I45: https://cadwr.box.com/s/qm8lwwmzfxl20b40d8axkyb6125cjrrp | L45: Both | N45: TAF
B46: CALSIM | C46: GW1_N1006 | D46: BUGW-INFLOW | E46: 1MON | F46: L2020A | G46: =_xlfn.CONCAT(C46,"/",D46) -> GW1_N1006/BUGW-INFLOW | H46: Groundwater Models | I46: https://cadwr.box.com/s/qm8lwwmzfxl20b40d8axkyb6125cjrrp | L46: Both | N46: TAF
B47: CALSIM | C47: GW1_N1007 | D47: BUGW-INFLOW | E47: 1MON | F47: L2020A | G47: =_xlfn.CONCAT(C47,"/",D47) -> GW1_N1007/BUGW-INFLOW | H47: Groundwater Models | I47: https://cadwr.box.com/s/qm8lwwmzfxl20b40d8axkyb6125cjrrp | L47: Both | N47: TAF
B48: CALSIM | C48: GW1_N1017 | D48: BUGW-INFLOW | E48: 1MON | F48: L2020A | G48: =_xlfn.CONCAT(C48,"/",D48) -> GW1_N1017/BUGW-INFLOW | H48: Groundwater Models | I48: https://cadwr.box.com/s/qm8lwwmzfxl20b40d8axkyb6125cjrrp | L48: Both | N48: TAF
B49: CALSIM | C49: GW1_N1034 | D49: BUGW-INFLOW | E49: 1MON | F49: L2020A | G49: =_xlfn.CONCAT(C49,"/",D49) -> GW1_N1034/BUGW-INFLOW | H49: Groundwater Models | I49: https://cadwr.box.com/s/qm8lwwmzfxl20b40d8axkyb6125cjrrp | L49: Both | N49: TAF
B50: CALSIM | C50: GW1_N1035 | D50: BUGW-INFLOW | E50: 1MON | F50: L2020A | G50: =_xlfn.CONCAT(C50,"/",D50) -> GW1_N1035/BUGW-INFLOW | H50: Groundwater Models | I50: https://cadwr.box.com/s/qm8lwwmzfxl20b40d8axkyb6125cjrrp | L50: Both | N50: TAF
B51: CALSIM | C51: GW1_N1036 | D51: BUGW-INFLOW | E51: 1MON | F51: L2020A | G51: =_xlfn.CONCAT(C51,"/",D51) -> GW1_N1036/BUGW-INFLOW | H51: Groundwater Models | I51: https://cadwr.box.com/s/qm8lwwmzfxl20b40d8axkyb6125cjrrp | L51: Both | N51: TAF
B52: CALSIM | C52: GW1_N1051 | D52: BUGW-INFLOW | E52: 1MON | F52: L2020A | G52: =_xlfn.CONCAT(C52,"/",D52) -> GW1_N1051/BUGW-INFLOW | H52: Groundwater Models | I52: https://cadwr.box.com/s/qm8lwwmzfxl20b40d8axkyb6125cjrrp | L52: Both | N52: TAF
...

Sheet MASTER
B2: A | C2: B | D2: C | E2: D | F2: E | G2: F | H2: UID | I2: Input_Category | J2: CS3 SV Composer | K2: Missing | L2: Constant/Rept | M2: Used in DCR | N2: Input Basis | O2: Input Procedure | P2: R2
B3: CALSIM | C3: AWO_02_NA | D3: APPLIED-WATER | E3: * | F3: 1MON | G3: L2020A | H3: =_xlfn.CONCAT(C3,"/",D3) -> AWO_02_NA/APPLIED-WATER | I3: CalSimHydro | J3: =VLOOKUP(Table1[[#This Row],[UID]],CS3SVComposerConfig!$B$3:$D$1808,3,FALSE) -> CS3L2015V0Hydro_SV.dss | K3: F | L3: F | M3: T | N3: WGEN | O3: Model | P3: N/A
B4: CALSIM | C4: AWO_02_PA | D4: APPLIED-WATER | E4: * | F4: 1MON | G4: L2020A | H4: =_xlfn.CONCAT(C4,"/",D4) -> AWO_02_PA/APPLIED-WATER | I4: CalSimHydro | J4: =VLOOKUP(Table1[[#This Row],[UID]],CS3SVComposerConfig!$B$3:$D$1808,3,FALSE) -> CS3L2015V0Hydro_SV.dss | K4: F | L4: F | M4: T | N4: WGEN | O4: Model | P4: N/A
B5: CALSIM | C5: AWO_02_SA | D5: APPLIED-WATER | E5: * | F5: 1MON | G5: L2020A | H5: =_xlfn.CONCAT(C5,"/",D5) -> AWO_02_SA/APPLIED-WATER | I5: CalSimHydro | J5: =VLOOKUP(Table1[[#This Row],[UID]],CS3SVComposerConfig!$B$3:$D$1808,3,FALSE) -> CS3L2015V0Hydro_SV.dss | K5: F | L5: F | M5: T | N5: WGEN | O5: Model | P5: N/A
B6: CALSIM | C6: AWO_03_NA | D6: APPLIED-WATER | E6: * | F6: 1MON | G6: L2020A | H6: =_xlfn.CONCAT(C6,"/",D6) -> AWO_03_NA/APPLIED-WATER | I6: CalSimHydro | J6: =VLOOKUP(Table1[[#This Row],[UID]],CS3SVComposerConfig!$B$3:$D$1808,3,FALSE) -> CS3L2015V0Hydro_SV.dss | K6: F | L6: F | M6: T | N6: WGEN | O6: Model | P6: N/A
B7: CALSIM | C7: AWO_03_PA | D7: APPLIED-WATER | E7: * | F7: 1MON | G7: L2020A | H7: =_xlfn.CONCAT(C7,"/",D7) -> AWO_03_PA/APPLIED-WATER | I7: CalSimHydro | J7: =VLOOKUP(Table1[[#This Row],[UID]],CS3SVComposerConfig!$B$3:$D$1808,3,FALSE) -> CS3L2015V0Hydro_SV.dss | K7: F | L7: F | M7: T | N7: WGEN | O7: Model | P7: N/A
B8: CALSIM | C8: AWO_03_SA | D8: APPLIED-WATER | E8: * | F8: 1MON | G8: L2020A | H8: =_xlfn.CONCAT(C8,"/",D8) -> AWO_03_SA/APPLIED-WATER | I8: CalSimHydro | J8: =VLOOKUP(Table1[[#This Row],[UID]],CS3SVComposerConfig!$B$3:$D$1808,3,FALSE) -> CS3L2015V0Hydro_SV.dss | K8: F | L8: F | M8: T | N8: WGEN | O8: Model | P8: N/A
B9: CALSIM | C9: AWO_04_NA | D9: APPLIED-WATER | E9: * | F9: 1MON | G9: L2020A | H9: =_xlfn.CONCAT(C9,"/",D9) -> AWO_04_NA/APPLIED-WATER | I9: CalSimHydro | J9: =VLOOKUP(Table1[[#This Row],[UID]],CS3SVComposerConfig!$B$3:$D$1808,3,FALSE) -> CS3L2015V0Hydro_SV.dss | K9: F | L9: F | M9: T | N9: WGEN | O9: Model | P9: N/A
B10: CALSIM | C10: AWO_04_PA1 | D10: APPLIED-WATER | E10: * | F10: 1MON | G10: L2020A | H10: =_xlfn.CONCAT(C10,"/",D10) -> AWO_04_PA1/APPLIED-WATER | I10: CalSimHydro | J10: =VLOOKUP(Table1[[#This Row],[UID]],CS3SVComposerConfig!$B$3:$D$1808,3,FALSE) -> CS3L2015V0Hydro_SV.dss | K10: F | L10: F | M10: T | N10: WGEN | O10: Model | P10: N/A
B11: CALSIM | C11: AWO_04_PA2 | D11: APPLIED-WATER | E11: * | F11: 1MON | G11: L2020A | H11: =_xlfn.CONCAT(C11,"/",D11) -> AWO_04_PA2/APPLIED-WATER | I11: CalSimHydro | J11: =VLOOKUP(Table1[[#This Row],[UID]],CS3SVComposerConfig!$B$3:$D$1808,3,FALSE) -> CS3L2015V0Hydro_SV.dss | K11: F | L11: F | M11: T | N11: WGEN | O11: Model | P11: N/A
B12: CALSIM | C12: AWO_05_NA | D12: APPLIED-WATER | E12: * | F12: 1MON | G12: L2020A | H12: =_xlfn.CONCAT(C12,"/",D12) -> AWO_05_NA/APPLIED-WATER | I12: CalSimHydro | J12: =VLOOKUP(Table1[[#This Row],[UID]],CS3SVComposerConfig!$B$3:$D$1808,3,FALSE) -> CS3L2015V0Hydro_SV.dss | K12: F | L12: F | M12: T | N12: WGEN | O12: Model | P12: N/A
B13: CALSIM | C13: AWO_06_NA | D13: APPLIED-WATER | E13: * | F13: 1MON | G13: L2020A | H13: =_xlfn.CONCAT(C13,"/",D13) -> AWO_06_NA/APPLIED-WATER | I13: CalSimHydro | J13: =VLOOKUP(Table1[[#This Row],[UID]],CS3SVComposerConfig!$B$3:$D$1808,3,FALSE) -> CS3L2015V0Hydro_SV.dss | K13: F | L13: F | M13: T | N13: WGEN | O13: Model | P13: N/A
B14: CALSIM | C14: AWO_06_PA | D14: APPLIED-WATER | E14: * | F14: 1MON | G14: L2020A | H14: =_xlfn.CONCAT(C14,"/",D14) -> AWO_06_PA/APPLIED-WATER | I14: CalSimHydro | J14: =VLOOKUP(Table1[[#This Row],[UID]],CS3SVComposerConfig!$B$3:$D$1808,3,FALSE) -> CS3L2015V0Hydro_SV.dss | K14: F | L14: F | M14: T | N14: WGEN | O14: Model | P14: N/A
... B848: CALSIM | C848: CT_YOLO_SV | D848: CLOSURE-TERM | E848: * | F848: 1MON | G848: L2020A | H848: =_xlfn.CONCAT(C848,"/",D848) -> CT_YOLO_SV/CLOSURE-TERM | I848: Closure Terms | J848: =VLOOKUP(Table1[[#This Row],[UID]],CS3SVComposerConfig!$B$3:$D$1808,3,FALSE) -> ClosureTerms.dss | K848: T | L848: F | M848: T | N848: N/A | O848: N/A | P848: N/A
B849: CALSIM | C849: DAY1 | D849: VOL-FRACTION | E849: * | F849: 1MON | G849: L2020A | H849: =_xlfn.CONCAT(C849,"/",D849) -> DAY1/VOL-FRACTION | I849: Day-Volume Fraction | J849: =VLOOKUP(Table1[[#This Row],[UID]],CS3SVComposerConfig!$B$3:$D$1808,3,FALSE) -> DCR2023_SV_Danube_Hist_v3.dss | K849: F | L849: F | M849: T | N849: VIC | O849: Bootstrapping | P849: 0
B850: CALSIM | C850: DAY10 | D850: VOL-FRACTION | E850: * | F850: 1MON | G850: L2020A | H850: =_xlfn.CONCAT(C850,"/",D850) -> DAY10/VOL-FRACTION | I850: Day-Volume Fraction | J850: =VLOOKUP(Table1[[#This Row],[UID]],CS3SVComposerConfig!$B$3:$D$1808,3,FALSE) -> DCR2023_SV_Danube_Hist_v3.dss | K850: F | L850: F | M850: T | N850: VIC | O850: Bootstrapping | P850: 0
B851: CALSIM | C851: DAY11 | D851: VOL-FRACTION | E851: * | F851: 1MON | G851: L2020A | H851: =_xlfn.CONCAT(C851,"/",D851) -> DAY11/VOL-FRACTION | I851: Day-Volume Fraction | J851: =VLOOKUP(Table1[[#This Row],[UID]],CS3SVComposerConfig!$B$3:$D$1808,3,FALSE) -> DCR2023_SV_Danube_Hist_v3.dss | K851: F | L851: F | M851: T | N851: VIC | O851: Bootstrapping | P851: 0
B852: CALSIM | C852: DAY12 | D852: VOL-FRACTION | E852: * | F852: 1MON | G852: L2020A | H852: =_xlfn.CONCAT(C852,"/",D852) -> DAY12/VOL-FRACTION | I852: Day-Volume Fraction | J852: =VLOOKUP(Table1[[#This Row],[UID]],CS3SVComposerConfig!$B$3:$D$1808,3,FALSE) -> DCR2023_SV_Danube_Hist_v3.dss | K852: F | L852: F | M852: T | N852: VIC | O852: Bootstrapping | P852: 0
B853: CALSIM | C853: DAY13 | D853: VOL-FRACTION | E853: * | F853: 1MON | G853: L2020A | H853: =_xlfn.CONCAT(C853,"/",D853) -> DAY13/VOL-FRACTION | I853: Day-Volume Fraction | J853: =VLOOKUP(Table1[[#This Row],[UID]],CS3SVComposerConfig!$B$3:$D$1808,3,FALSE) -> DCR2023_SV_Danube_Hist_v3.dss | K853: F | L853: F | M853: T | N853: VIC | O853: Bootstrapping | P853: 0
B854: CALSIM | C854: DAY14 | D854: VOL-FRACTION | E854: * | F854: 1MON | G854: L2020A | H854: =_xlfn.CONCAT(C854,"/",D854) -> DAY14/VOL-FRACTION | I854: Day-Volume Fraction | J854: =VLOOKUP(Table1[[#This Row],[UID]],CS3SVComposerConfig!$B$3:$D$1808,3,FALSE) -> DCR2023_SV_Danube_Hist_v3.dss | K854: F | L854: F | M854: T | N854: VIC | O854: Bootstrapping | P854: 0
B855: CALSIM | C855: DAY15 | D855: VOL-FRACTION | E855: * | F855: 1MON | G855: L2020A | H855: =_xlfn.CONCAT(C855,"/",D855) -> DAY15/VOL-FRACTION | I855: Day-Volume Fraction | J855: =VLOOKUP(Table1[[#This Row],[UID]],CS3SVComposerConfig!$B$3:$D$1808,3,FALSE) -> DCR2023_SV_Danube_Hist_v3.dss | K855: F | L855: F | M855: T | N855: VIC | O855: Bootstrapping | P855: 0
B856: CALSIM | C856: DAY16 | D856: VOL-FRACTION | E856: * | F856: 1MON | G856: L2020A | H856: =_xlfn.CONCAT(C856,"/",D856) -> DAY16/VOL-FRACTION | I856: Day-Volume Fraction | J856: =VLOOKUP(Table1[[#This Row],[UID]],CS3SVComposerConfig!$B$3:$D$1808,3,FALSE) -> DCR2023_SV_Danube_Hist_v3.dss | K856: F | L856: F | M856: T | N856: VIC | O856: Bootstrapping | P856: 0
B857: CALSIM | C857: DAY17 | D857: VOL-FRACTION | E857: * | F857: 1MON | G857: L2020A | H857: =_xlfn.CONCAT(C857,"/",D857) -> DAY17/VOL-FRACTION | I857: Day-Volume Fraction | J857: =VLOOKUP(Table1[[#This Row],[UID]],CS3SVComposerConfig!$B$3:$D$1808,3,FALSE) -> DCR2023_SV_Danube_Hist_v3.dss | K857: F | L857: F | M857: T | N857: VIC | O857: Bootstrapping | P857: 0
B858: CALSIM | C858: DAY18 | D858: VOL-FRACTION | E858: * | F858: 1MON | G858: L2020A | H858: =_xlfn.CONCAT(C858,"/",D858) -> DAY18/VOL-FRACTION | I858: Day-Volume Fraction | J858: =VLOOKUP(Table1[[#This Row],[UID]],CS3SVComposerConfig!$B$3:$D$1808,3,FALSE) -> DCR2023_SV_Danube_Hist_v3.dss | K858: F | L858: F | M858: T | N858: VIC | O858: Bootstrapping | P858: 0
B859: CALSIM | C859: DAY19 | D859: VOL-FRACTION | E859: * | F859: 1MON | G859: L2020A | H859: =_xlfn.CONCAT(C859,"/",D859) -> DAY19/VOL-FRACTION | I859: Day-Volume Fraction | J859: =VLOOKUP(Table1[[#This Row],[UID]],CS3SVComposerConfig!$B$3:$D$1808,3,FALSE) -> DCR2023_SV_Danube_Hist_v3.dss | K859: F | L859: F | M859: T | N859: VIC | O859: Bootstrapping | P859: 0
B860: CALSIM | C860: DAY2 | D860: VOL-FRACTION | E860: * | F860: 1MON | G860: L2020A | H860: =_xlfn.CONCAT(C860,"/",D860) -> DAY2/VOL-FRACTION | I860: Day-Volume Fraction | J860: =VLOOKUP(Table1[[#This Row],[UID]],CS3SVComposerConfig!$B$3:$D$1808,3,FALSE) -> DCR2023_SV_Danube_Hist_v3.dss | K860: F | L860: F | M860: T | N860: VIC | O860: Bootstrapping | P860: 0
... B879: CALSIM | C879: DAY9 | D879: VOL-FRACTION | E879: * | F879: 1MON | G879: L2020A | H879: =_xlfn.CONCAT(C879,"/",D879) -> DAY9/VOL-FRACTION | I879: Day-Volume Fraction | J879: =VLOOKUP(Table1[[#This Row],[UID]],CS3SVComposerConfig!$B$3:$D$1808,3,FALSE) -> DCR2023_SV_Danube_Hist_v3.dss | K879: F | L879: F | M879: T | N879: VIC | O879: Bootstrapping | P879: 0
B880: CALSIM | C880: DP_DELTA_DCD | D880: DP-FLOW | E880: * | F880: 1MON | G880: L2020A | H880: =_xlfn.CONCAT(C880,"/",D880) -> DP_DELTA_DCD/DP-FLOW | I880: Delta Channel Depletion | J880: =VLOOKUP(Table1[[#This Row],[UID]],CS3SVComposerConfig!$B$3:$D$1808,3,FALSE) -> DCD_island_month.dss | K880: F | L880: F | M880: T | N880: WGEN | O880: Model | P880: N/A
B881: CALSIM | C881: DP_WBA50_DCD | D881: DP-FLOW | E881: * | F881: 1MON | G881: L2020A | H881: =_xlfn.CONCAT(C881,"/",D881) -> DP_WBA50_DCD/DP-FLOW | I881: Delta Channel Depletion | J881: =VLOOKUP(Table1[[#This Row],[UID]],CS3SVComposerConfig!$B$3:$D$1808,3,FALSE) -> DCD_island_month.dss | K881: F | L881: F | M881: T | N881: WGEN | O881: Model | P881: N/A
B882: CALSIM | C882: DRN_50_PA2 | D882: DRN | E882: * | F882: 1MON | G882: L2020A | H882: =_xlfn.CONCAT(C882,"/",D882) -> DRN_50_PA2/DRN | I882: Delta Channel Depletion | J882: =VLOOKUP(Table1[[#This Row],[UID]],CS3SVComposerConfig!$B$3:$D$1808,3,FALSE) -> DCD_island_month.dss | K882: F | L882: F | M882: T | N882: WGEN | O882: Model | P882: N/A
B883: CALSIM | C883: DRN_MOK | D883: DRN | E883: * | F883: 1MON | G883: L2020A | H883: =_xlfn.CONCAT(C883,"/",D883) -> DRN_MOK/DRN | I883: Delta Channel Depletion | J883: =VLOOKUP(Table1[[#This Row],[UID]],CS3SVComposerConfig!$B$3:$D$1808,3,FALSE) -> DCD_island_month.dss | K883: F | L883: F | M883: T | N883: WGEN | O883: Model | P883: N/A
B884: CALSIM | C884: DRN_OMR | D884: DRN | E884: * | F884: 1MON | G884: L2020A | H884: =_xlfn.CONCAT(C884,"/",D884) -> DRN_OMR/DRN | I884: Delta Channel Depletion | J884: =VLOOKUP(Table1[[#This Row],[UID]],CS3SVComposerConfig!$B$3:$D$1808,3,FALSE) -> DCD_island_month.dss | K884: F | L884: F | M884: T | N884: WGEN | O884: Model | P884: N/A
B885: CALSIM | C885: DRN_SAC_NORTH | D885: DRN | E885: * | F885: 1MON | G885: L2020A | H885: =_xlfn.CONCAT(C885,"/",D885) -> DRN_SAC_NORTH/DRN | I885: Delta Channel Depletion | J885: =VLOOKUP(Table1[[#This Row],[UID]],CS3SVComposerConfig!$B$3:$D$1808,3,FALSE) -> DCD_island_month.dss | K885: F | L885: F | M885: T | N885: WGEN | O885: Model | P885: N/A
B886: CALSIM | C886: DRN_SAC_SOUTH | D886: DRN | E886: * | F886: 1MON | G886: L2020A | H886: =_xlfn.CONCAT(C886,"/",D886) -> DRN_SAC_SOUTH/DRN | I886: Delta Channel Depletion | J886: =VLOOKUP(Table1[[#This Row],[UID]],CS3SVComposerConfig!$B$3:$D$1808,3,FALSE) -> DCD_island_month.dss | K886: F | L886: F | M886: T | N886: WGEN | O886: Model | P886: N/A
B887: CALSIM | C887: DRN_SAC_WEST | D887: DRN | E887: * | F887: 1MON | G887: L2020A | H887: =_xlfn.CONCAT(C887,"/",D887) -> DRN_SAC_WEST/DRN | I887: Delta Channel Depletion | J887: =VLOOKUP(Table1[[#This Row],[UID]],CS3SVComposerConfig!$B$3:$D$1808,3,FALSE) -> DCD_island_month.dss | K887: F | L887: F | M887: T | N887: WGEN | O887: Model | P887: N/A
B888: CALSIM | C888: DRN_SJR_EAST | D888: DRN | E888: * | F888: 1MON | G888: L2020A | H888: =_xlfn.CONCAT(C888,"/",D888) -> DRN_SJR_EAST/DRN | I888: Delta Channel Depletion | J888: =VLOOKUP(Table1[[#This Row],[UID]],CS3SVComposerConfig!$B$3:$D$1808,3,FALSE) -> DCD_island_month.dss | K888: F | L888: F | M888: T | N888: WGEN | O888: Model | P888: N/A
B889: CALSIM | C889: DRN_SJR_WEST | D889: DRN | E889: * | F889: 1MON | G889: L2020A | H889: =_xlfn.CONCAT(C889,"/",D889) -> DRN_SJR_WEST/DRN | I889: Delta Channel Depletion | J889: =VLOOKUP(Table1[[#This Row],[UID]],CS3SVComposerConfig!$B$3:$D$1808,3,FALSE) -> DCD_island_month.dss | K889: F | L889: F | M889: T | N889: WGEN | O889: Model | P889: N/A
B890: CALSIM | C890: GW_DELTA_DCD | D890: GW-FLOW | E890: * | F890: 1MON | G890: L2020A | H890: =_xlfn.CONCAT(C890,"/",D890) -> GW_DELTA_DCD/GW-FLOW | I890: Delta Channel Depletion | J890: =VLOOKUP(Table1[[#This Row],[UID]],CS3SVComposerConfig!$B$3:$D$1808,3,FALSE) -> DCD_island_month.dss | K890: F | L890: F | M890: T | N890: WGEN | O890: Model | P890: N/A
B891: CALSIM | C891: GW_WBA50_DCD | D891: GW-FLOW | E891: * | F891: 1MON | G891: L2020A | H891: =_xlfn.CONCAT(C891,"/",D891) -> GW_WBA50_DCD/GW-FLOW | I891: Delta Channel Depletion | J891: =VLOOKUP(Table1[[#This Row],[UID]],CS3SVComposerConfig!$B$3:$D$1808,3,FALSE) -> DCD_island_month.dss | K891: F | L891: F | M891: T | N891: WGEN | O891: Model | P891: N/A
... B908: CALSIM | C908: MF_KSWCK | D908: FLOW-MIN-REQUIRED | E908: * | F908: 1MON | G908: L2020A | H908: =_xlfn.CONCAT(C908,"/",D908) -> MF_KSWCK/FLOW-MIN-REQUIRED | I908: Instream Flows | J908: =VLOOKUP(Table1[[#This Row],[UID]],CS3SVComposerConfig!$B$3:$D$1808,3,FALSE) -> DCR2023_SV_Danube_Hist_v3.dss | K908: F | L908: T | M908: T | N908: Copy | O908: Copy | P908: N/A
...

Sheet SummaryCounts
D2: =SUM(D4:D18) -> 1375 | E2: =SUM(E4:E18) -> 32 | F2: =SUM(F4:F18) -> 220 | G2: =SUM(G4:G18) -> 106 | H2: =SUM(H4:H18) -> 1733 | I2: =SUM(I4:I18) -> 1
B3: Status | C3: Input Category | D3: Total Count (Generate) | E3: Missing Values | F3: Constant or Repeating Values | G3: Not Used in DCR 2023 or Dynamic | H3: Total Count | I3: Total Pct
B4: x | C4: {=_xlfn._xlws.SORT(_xlfn.UNIQUE(Table1[Input_Category]))} -> CalSimHydro | D4: =H4-SUM(E4:G4) -> 655 | E4: =COUNTIFS(Table1[Input_Category],"="&C4, Table1[Missing],"="&"T") -> 0 | F4: =COUNTIFS(Table1[Input_Category],"="&C4, Table1[Constant/Rept],"="&"T") -> 91 | G4: =COUNTIFS(Table1[Input_Category],"="&C4, Table1[Used in DCR],"="&"F") -> 0 | H4: =COUNTIFS(Table1[Input_Category],"="&C4) -> 746 | I4: =H4/SUM($H$4:$H$21) -> 0.4304674 | J4: =SUM(E4:G4) -> 91
B5: x | C5: CalSimHydroEE | D5: =H5-SUM(E5:G5) -> 17 | E5: =COUNTIFS(Table1[Input_Category],"="&C5, Table1[Missing],"="&"T") -> 0 | F5: =COUNTIFS(Table1[Input_Category],"="&C5, Table1[Constant/Rept],"="&"T") -> 0 | G5: =COUNTIFS(Table1[Input_Category],"="&C5, Table1[Used in DCR],"="&"F") -> 0 | H5: =COUNTIFS(Table1[Input_Category],"="&C5) -> 17 | I5: =H5/SUM($H$4:$H$21) -> 0.0098095788 | J5: =SUM(E5:G5) -> 0
B6: x | C6: Climate | D6: =H6-SUM(E6:G6) -> 56 | E6: =COUNTIFS(Table1[Input_Category],"="&C6, Table1[Missing],"="&"T") -> 0 | F6: =COUNTIFS(Table1[Input_Category],"="&C6, Table1[Constant/Rept],"="&"T") -> 0 | G6: =COUNTIFS(Table1[Input_Category],"="&C6, Table1[Used in DCR],"="&"F") -> 1 | H6: =COUNTIFS(Table1[Input_Category],"="&C6) -> 57 | I6: =H6/SUM($H$4:$H$21) -> 0.032890941 | J6: =SUM(E6:G6) -> 1
B7: x | C7: Closure Terms | D7: =H7-SUM(E7:G7) -> 13 | E7: =COUNTIFS(Table1[Input_Category],"="&C7, Table1[Missing],"="&"T") -> 5 | F7: =COUNTIFS(Table1[Input_Category],"="&C7, Table1[Constant/Rept],"="&"T") -> 8 | G7: =COUNTIFS(Table1[Input_Category],"="&C7, Table1[Used in DCR],"="&"F") -> 0 | H7: =COUNTIFS(Table1[Input_Category],"="&C7) -> 26 | I7: =H7/SUM($H$4:$H$21) -> 0.015002885 | J7: =SUM(E7:G7) -> 13
B8: x | C8: Day-Volume Fraction | D8: =H8-SUM(E8:G8) -> 31 | E8: =COUNTIFS(Table1[Input_Category],"="&C8, Table1[Missing],"="&"T") -> 0 | F8: =COUNTIFS(Table1[Input_Category],"="&C8, Table1[Constant/Rept],"="&"T") -> 0 | G8: =COUNTIFS(Table1[Input_Category],"="&C8, Table1[Used in DCR],"="&"F") -> 0 | H8: =COUNTIFS(Table1[Input_Category],"="&C8) -> 31 | I8: =H8/SUM($H$4:$H$21) -> 0.017888055 | J8: =SUM(E8:G8) -> 0
B9: x | C9: Delta Channel Depletion | D9: =H9-SUM(E9:G9) -> 28 | E9: =COUNTIFS(Table1[Input_Category],"="&C9, Table1[Missing],"="&"T") -> 0 | F9: =COUNTIFS(Table1[Input_Category],"="&C9, Table1[Constant/Rept],"="&"T") -> 0 | G9: =COUNTIFS(Table1[Input_Category],"="&C9, Table1[Used in DCR],"="&"F") -> 0 | H9: =COUNTIFS(Table1[Input_Category],"="&C9) -> 28 | I9: =H9/SUM($H$4:$H$21) -> 0.016156953 | J9: =SUM(E9:G9) -> 0
B10: x | C10: Instream Flows | D10: =H10-SUM(E10:G10) -> 3 | E10: =COUNTIFS(Table1[Input_Category],"="&C10, Table1[Missing],"="&"T") -> 0 | F10: =COUNTIFS(Table1[Input_Category],"="&C10, Table1[Constant/Rept],"="&"T") -> 1 | G10: =COUNTIFS(Table1[Input_Category],"="&C10, Table1[Used in DCR],"="&"F") -> 2 | H10: =COUNTIFS(Table1[Input_Category],"="&C10) -> 6 | I10: =H10/SUM($H$4:$H$21) -> 0.0034622043 | J10: =SUM(E10:G10) -> 3
B11: x | C11: Other | D11: =H11-SUM(E11:G11) -> 7 | E11: =COUNTIFS(Table1[Input_Category],"="&C11, Table1[Missing],"="&"T") -> 13 | F11: =COUNTIFS(Table1[Input_Category],"="&C11, Table1[Constant/Rept],"="&"T") -> 110 | G11: =COUNTIFS(Table1[Input_Category],"="&C11, Table1[Used in DCR],"="&"F") -> 13 | H11: =COUNTIFS(Table1[Input_Category],"="&C11) -> 143 | I11: =H11/SUM($H$4:$H$21) -> 0.082515868 | J11: =SUM(E11:G11) -> 136
B12: x | C12: Reservoir Evaporation | D12: =H12-SUM(E12:G12) -> 95 | E12: =COUNTIFS(Table1[Input_Category],"="&C12, Table1[Missing],"="&"T") -> 1 | F12: =COUNTIFS(Table1[Input_Category],"="&C12, Table1[Constant/Rept],"="&"T") -> 0 | G12: =COUNTIFS(Table1[Input_Category],"="&C12, Table1[Used in DCR],"="&"F") -> 0 | H12: =COUNTIFS(Table1[Input_Category],"="&C12) -> 96 | I12: =H12/SUM($H$4:$H$21) -> 0.055395268 | J12: =SUM(E12:G12) -> 1
B13: x | C13: Reservoir Storage Curves | D13: =H13-SUM(E13:G13) -> 7 | E13: =COUNTIFS(Table1[Input_Category],"="&C13, Table1[Missing],"="&"T") -> 0 | F13: =COUNTIFS(Table1[Input_Category],"="&C13, Table1[Constant/Rept],"="&"T") -> 2 | G13: =COUNTIFS(Table1[Input_Category],"="&C13, Table1[Used in DCR],"="&"F") -> 0 | H13: =COUNTIFS(Table1[Input_Category],"="&C13) -> 9 | I13: =H13/SUM($H$4:$H$21) -> 0.0051933064 | J13: =SUM(E13:G13) -> 2
B14: x | C14: Rim Inflow | D14: =H14-SUM(E14:G14) -> 227 | E14: =COUNTIFS(Table1[Input_Category],"="&C14, Table1[Missing],"="&"T") -> 13 | F14: =COUNTIFS(Table1[Input_Category],"="&C14, Table1[Constant/Rept],"="&"T") -> 0 | G14: =COUNTIFS(Table1[Input_Category],"="&C14, Table1[Used in DCR],"="&"F") -> 1 | H14: =COUNTIFS(Table1[Input_Category],"="&C14) -> 241 | I14: =H14/SUM($H$4:$H$21) -> 0.1390652 | J14: =SUM(E14:G14) -> 14
B15: x | C15: Salinity | D15: =H15-SUM(E15:G15) -> 0 | E15: =COUNTIFS(Table1[Input_Category],"="&C15, Table1[Missing],"="&"T") -> 0 | F15: =COUNTIFS(Table1[Input_Category],"="&C15, Table1[Constant/Rept],"="&"T") -> 5 | G15: =COUNTIFS(Table1[Input_Category],"="&C15, Table1[Used in DCR],"="&"F") -> 0 | H15: =COUNTIFS(Table1[Input_Category],"="&C15) -> 5 | I15: =H15/SUM($H$4:$H$21) -> 0.0028851702 | J15: =SUM(E15:G15) -> 5
B16: x | C16: Small Watersheds | D16: =H16-SUM(E16:G16) -> 210 | E16: =COUNTIFS(Table1[Input_Category],"="&C16, Table1[Missing],"="&"T") -> 0 | F16: =COUNTIFS(Table1[Input_Category],"="&C16, Table1[Constant/Rept],"="&"T") -> 0 | G16: =COUNTIFS(Table1[Input_Category],"="&C16, Table1[Used in DCR],"="&"F") -> 0 | H16: =COUNTIFS(Table1[Input_Category],"="&C16) -> 210 | I16: =H16/SUM($H$4:$H$21) -> 0.12117715 | J16: =SUM(E16:G16) -> 0
... B18: x | C18: Upper Watershed Modules | D18: =H18-SUM(E18:G18) -> 12 | E18: =COUNTIFS(Table1[Input_Category],"="&C18, Table1[Missing],"="&"T") -> 0 | F18: =COUNTIFS(Table1[Input_Category],"="&C18, Table1[Constant/Rept],"="&"T") -> 3 | G18: =COUNTIFS(Table1[Input_Category],"="&C18, Table1[Used in DCR],"="&"F") -> 89 | H18: =COUNTIFS(Table1[Input_Category],"="&C18) -> 104 | I18: =H18/SUM($H$4:$H$21) -> 0.060011541 | J18: =SUM(E18:G18) -> 92

Sheet CS3SVComposerConfig
F1: =COUNT(F3:F10000) -> 1758
B2: uid | C2: csv | D2: dss | E2: L2015 | F2: idx | G2: L2020 | H2: Part A | I2: Part B | J2: Part C | K2: Part D | L2: Part E | M2: Part F | N2: Duplicated? | O2: Match in Inventory?
B3: =_xlfn.CONCAT(I3,"/",J3) -> AWO_50_PA1/APPLIED-WATER | C3: LTO_Hydro_L2015A_to_L2020A_SJRrebal_cp.csv | D3: RebalancedSJR_AW_TW_DP.dss | E3: /CALSIM/AWO_50_PA1/APPLIED-WATER//1MON/L2015A/ | F3: 1 | G3: /CALSIM/AWO_50_PA1/APPLIED-WATER//1MON/L2020A/ | H3: CALSIM | I3: AWO_50_PA1 | J3: APPLIED-WATER | L3: 1MON | M3: L2020A | N3: =IF(COUNTIF($B$3:$B$1760,"="&B3)>1,"T","F") -> F | O3: =IF(_xlfn.IFNA(MATCH(B3,Table1[UID],0),"F")="F","F","T") -> T
B4: =_xlfn.CONCAT(I4,"/",J4) -> AWO_64_XA/APPLIED-WATER | C4: LTO_Hydro_L2015A_to_L2020A_SJRrebal_cp.csv | D4: RebalancedSJR_AW_TW_DP.dss | E4: /CALSIM/AWO_64_XA/APPLIED-WATER//1MON/L2015A/ | F4: 2 | G4: /CALSIM/AWO_64_XA/APPLIED-WATER//1MON/L2020A/ | H4: CALSIM | I4: AWO_64_XA | J4: APPLIED-WATER | L4: 1MON | M4: L2020A | N4: =IF(COUNTIF($B$3:$B$1760,"="&B4)>1,"T","F") -> F | O4: =IF(_xlfn.IFNA(MATCH(B4,Table1[UID],0),"F")="F","F","T") -> T
B5: =_xlfn.CONCAT(I5,"/",J5) -> AWO_71_PA1/APPLIED-WATER | C5: LTO_Hydro_L2015A_to_L2020A_SJRrebal_cp.csv | D5: RebalancedSJR_AW_TW_DP.dss | E5: /CALSIM/AWO_71_PA1/APPLIED-WATER//1MON/L2015A/ | F5: 3 | G5: /CALSIM/AWO_71_PA1/APPLIED-WATER//1MON/L2020A/ | H5: CALSIM | I5: AWO_71_PA1 | J5: APPLIED-WATER | L5: 1MON | M5: L2020A | N5: =IF(COUNTIF($B$3:$B$1760,"="&B5)>1,"T","F") -> F | O5: =IF(_xlfn.IFNA(MATCH(B5,Table1[UID],0),"F")="F","F","T") -> T
B6: =_xlfn.CONCAT(I6,"/",J6) -> AWO_71_PA2/APPLIED-WATER | C6: LTO_Hydro_L2015A_to_L2020A_SJRrebal_cp.csv | D6: RebalancedSJR_AW_TW_DP.dss | E6: /CALSIM/AWO_71_PA2/APPLIED-WATER//1MON/L2015A/ | F6: 4 | G6: /CALSIM/AWO_71_PA2/APPLIED-WATER//1MON/L2020A/ | H6: CALSIM | I6: AWO_71_PA2 | J6: APPLIED-WATER | L6: 1MON | M6: L2020A | N6: =IF(COUNTIF($B$3:$B$1760,"="&B6)>1,"T","F") -> F | O6: =IF(_xlfn.IFNA(MATCH(B6,Table1[UID],0),"F")="F","F","T") -> T
B7: =_xlfn.CONCAT(I7,"/",J7) -> AWO_71_PA3/APPLIED-WATER | C7: LTO_Hydro_L2015A_to_L2020A_SJRrebal_cp.csv | D7: RebalancedSJR_AW_TW_DP.dss | E7: /CALSIM/AWO_71_PA3/APPLIED-WATER//1MON/L2015A/ | F7: 5 | G7: /CALSIM/AWO_71_PA3/APPLIED-WATER//1MON/L2020A/ | H7: CALSIM | I7: AWO_71_PA3 | J7: APPLIED-WATER | L7: 1MON | M7: L2020A | N7: =IF(COUNTIF($B$3:$B$1760,"="&B7)>1,"T","F") -> F | O7: =IF(_xlfn.IFNA(MATCH(B7,Table1[UID],0),"F")="F","F","T") -> T
B8: =_xlfn.CONCAT(I8,"/",J8) -> AWO_71_PA4/APPLIED-WATER | C8: LTO_Hydro_L2015A_to_L2020A_SJRrebal_cp.csv | D8: RebalancedSJR_AW_TW_DP.dss | E8: /CALSIM/AWO_71_PA4/APPLIED-WATER//1MON/L2015A/ | F8: 6 | G8: /CALSIM/AWO_71_PA4/APPLIED-WATER//1MON/L2020A/ | H8: CALSIM | I8: AWO_71_PA4 | J8: APPLIED-WATER | L8: 1MON | M8: L2020A | N8: =IF(COUNTIF($B$3:$B$1760,"="&B8)>1,"T","F") -> F | O8: =IF(_xlfn.IFNA(MATCH(B8,Table1[UID],0),"F")="F","F","T") -> T
B9: =_xlfn.CONCAT(I9,"/",J9) -> AWO_71_PA5/APPLIED-WATER | C9: LTO_Hydro_L2015A_to_L2020A_SJRrebal_cp.csv | D9: RebalancedSJR_AW_TW_DP.dss | E9: /CALSIM/AWO_71_PA5/APPLIED-WATER//1MON/L2015A/ | F9: 7 | G9: /CALSIM/AWO_71_PA5/APPLIED-WATER//1MON/L2020A/ | H9: CALSIM | I9: AWO_71_PA5 | J9: APPLIED-WATER | L9: 1MON | M9: L2020A | N9: =IF(COUNTIF($B$3:$B$1760,"="&B9)>1,"T","F") -> F | O9: =IF(_xlfn.IFNA(MATCH(B9,Table1[UID],0),"F")="F","F","T") -> T
B10: =_xlfn.CONCAT(I10,"/",J10) -> AWO_71_PA6/APPLIED-WATER | C10: LTO_Hydro_L2015A_to_L2020A_SJRrebal_cp.csv | D10: RebalancedSJR_AW_TW_DP.dss | E10: /CALSIM/AWO_71_PA6/APPLIED-WATER//1MON/L2015A/ | F10: 8 | G10: /CALSIM/AWO_71_PA6/APPLIED-WATER//1MON/L2020A/ | H10: CALSIM | I10: AWO_71_PA6 | J10: APPLIED-WATER | L10: 1MON | M10: L2020A | N10: =IF(COUNTIF($B$3:$B$1760,"="&B10)>1,"T","F") -> F | O10: =IF(_xlfn.IFNA(MATCH(B10,Table1[UID],0),"F")="F","F","T") -> T
B11: =_xlfn.CONCAT(I11,"/",J11) -> AWO_71_PA7/APPLIED-WATER | C11: LTO_Hydro_L2015A_to_L2020A_SJRrebal_cp.csv | D11: RebalancedSJR_AW_TW_DP.dss | E11: /CALSIM/AWO_71_PA7/APPLIED-WATER//1MON/L2015A/ | F11: 9 | G11: /CALSIM/AWO_71_PA7/APPLIED-WATER//1MON/L2020A/ | H11: CALSIM | I11: AWO_71_PA7 | J11: APPLIED-WATER | L11: 1MON | M11: L2020A | N11: =IF(COUNTIF($B$3:$B$1760,"="&B11)>1,"T","F") -> F | O11: =IF(_xlfn.IFNA(MATCH(B11,Table1[UID],0),"F")="F","F","T") -> T
B12: =_xlfn.CONCAT(I12,"/",J12) -> AWO_71_PA8/APPLIED-WATER | C12: LTO_Hydro_L2015A_to_L2020A_SJRrebal_cp.csv | D12: RebalancedSJR_AW_TW_DP.dss | E12: /CALSIM/AWO_71_PA8/APPLIED-WATER//1MON/L2015A/ | F12: 10 | G12: /CALSIM/AWO_71_PA8/APPLIED-WATER//1MON/L2020A/ | H12: CALSIM | I12: AWO_71_PA8 | J12: APPLIED-WATER | L12: 1MON | M12: L2020A | N12: =IF(COUNTIF($B$3:$B$1760,"="&B12)>1,"T","F") -> F | O12: =IF(_xlfn.IFNA(MATCH(B12,Table1[UID],0),"F")="F","F","T") -> T
B13: =_xlfn.CONCAT(I13,"/",J13) -> AWO_72_PA/APPLIED-WATER | C13: LTO_Hydro_L2015A_to_L2020A_SJRrebal_cp.csv | D13: RebalancedSJR_AW_TW_DP.dss | E13: /CALSIM/AWO_72_PA/APPLIED-WATER//1MON/L2015A/ | F13: 11 | G13: /CALSIM/AWO_72_PA/APPLIED-WATER//1MON/L2020A/ | H13: CALSIM | I13: AWO_72_PA | J13: APPLIED-WATER | L13: 1MON | M13: L2020A | N13: =IF(COUNTIF($B$3:$B$1760,"="&B13)>1,"T","F") -> F | O13: =IF(_xlfn.IFNA(MATCH(B13,Table1[UID],0),"F")="F","F","T") -> T
B14: =_xlfn.CONCAT(I14,"/",J14) -> AWO_72_PR1/APPLIED-WATER | C14: LTO_Hydro_L2015A_to_L2020A_SJRrebal_cp.csv | D14: RebalancedSJR_AW_TW_DP.dss | E14: /CALSIM/AWO_72_PR1/APPLIED-WATER//1MON/L2015A/ | F14: 12 | G14: /CALSIM/AWO_72_PR1/APPLIED-WATER//1MON/L2020A/ | H14: CALSIM | I14: AWO_72_PR1 | J14: APPLIED-WATER | L14: 1MON | M14: L2020A | N14: =IF(COUNTIF($B$3:$B$1760,"="&B14)>1,"T","F") -> F | O14: =IF(_xlfn.IFNA(MATCH(B14,Table1[UID],0),"F")="F","F","T") -> T
... B1760: =_xlfn.CONCAT(I1760,"/",J1760) -> I_OROVL/INFLOW | C1760: LTOhis_CS3SV_Rim_218Inflow_cp | D1760: adj_SV_CS3LTO_0803_riminflow20231214.dss | E1760: /CALSIM/I_OROVL/INFLOW//1MON/L2020ADJ/ | F1760: 218 | G1760: /CALSIM/I_OROVL/INFLOW//1MON/L2020A/ | H1760: CALSIM | I1760: I_OROVL | J1760: INFLOW | L1760: 1MON | M1760: L2020A | N1760: =IF(COUNTIF($B$3:$B$1760,"="&B1760)>1,"T","F") -> F | O1760: =IF(_xlfn.IFNA(MATCH(B1760,Table1[UID],0),"F")="F","F","T") -> T
